Workbook

Sheet Resumo
A1: Data | B1: PIB | C1: IGPDI | D1: ICMS | E1: ICMS_cheio | I1: Ressarcimento ST | J1: Cred_AC | K1: TOTAL | N1: ICMS R$
A2: 38384 | B2: 73.00286 | C2: 329.241 | D2: 3877.7237 | E2: =D2+K2 -> 4013.688 | I2: 22.29928 | J2: 113.66507 | K2: =I2+J2 -> 135.96435 | N2: =D2*1000000 -> 3.8777237e+09
A3: 38412 | B3: 81.01825 | C3: 332.49 | D3: 3987.7632 | E3: =D3+K3 -> 4138.6993 | I3: 28.86961 | J3: 122.06654 | K3: =I3+J3 -> 150.93615 | N3: =D3*1000000 -> 3.9877632e+09
A4: 38443 | B4: 78.86227 | C4: 334.17 | D4: 4165.2361 | E4: =D4+K4 -> 4363.2531 | I4: 32.6881 | J4: 165.32893 | K4: =I4+J4 -> 198.01703 | N4: =D4*1000000 -> 4.1652361e+09
A5: 38473 | B5: 77.81578 | C5: 333.321 | D5: 4065.2091 | E5: =D5+K5 -> 4244.0884 | I5: 38.84619 | J5: 140.03318 | K5: =I5+J5 -> 178.87937 | N5: =D5*1000000 -> 4.0652091e+09
A6: 38504 | B6: 78.26167 | C6: 331.823 | D6: 4129.9117 | E6: =D6+K6 -> 4346.28 | I6: 40.31196 | J6: 176.05636 | K6: =I6+J6 -> 216.36832 | N6: =D6*1000000 -> 4.1299117e+09
A7: 38534 | B7: 79.42463 | C7: 330.484 | D7: 4103.8062 | E7: =D7+K7 -> 4336.0482 | I7: 30.99574 | J7: 201.24626 | K7: =I7+J7 -> 232.242 | N7: =D7*1000000 -> 4.1038062e+09
A8: 38565 | B8: 80.82781 | C8: 327.887 | D8: 4157.0969 | E8: =D8+K8 -> 4397.2245 | I8: 34.93208 | J8: 205.1955 | K8: =I8+J8 -> 240.12758 | N8: =D8*1000000 -> 4.1570969e+09
A9: 38596 | B9: 77.88061 | C9: 327.454 | D9: 4308.0149 | E9: =D9+K9 -> 4534.183 | I9: 25.16209 | J9: 201.00598 | K9: =I9+J9 -> 226.16807 | N9: =D9*1000000 -> 4.3080149e+09
A10: 38626 | B10: 78.14473 | C10: 329.529 | D10: 4337.2262 | E10: =D10+K10 -> 4559.2794 | I10: 24.92755 | J10: 197.12565 | K10: =I10+J10 -> 222.0532 | N10: =D10*1000000 -> 4.3372262e+09
A11: 38657 | B11: 78.42799 | C11: 330.619 | D11: 4367.0024 | E11: =D11+K11 -> 4583.1675 | I11: 31.35944 | J11: 184.8056 | K11: =I11+J11 -> 216.16504 | N11: =D11*1000000 -> 4.3670024e+09
A12: 38687 | B12: 78.08986 | C12: 330.835 | D12: 4540.3545 | E12: =D12+K12 -> 4661.1619 | I12: 29.90822 | J12: 90.89914 | K12: =I12+J12 -> 120.80736 | N12: =D12*1000000 -> 4.5403545e+09
A13: 38718 | B13: 76.19652 | C13: 333.222 | D13: 4500.8554 | E13: =D13+K13 -> 4690.7376 | I13: 34.52079 | J13: 155.36134 | K13: =I13+J13 -> 189.88213 | N13: =D13*1000000 -> 4.5008554e+09
... A167: 43405 | B167: 96.70731 | C167: 700.601 | D167: 11501.356 | E167: =D167+K167 -> 11956.72 | I167: 234.88743 | J167: 220.47609 | K167: =I167+J167 -> 455.36352 | N167: =D167*1000000 -> 1.1501356e+10
A168: 43435 | B168: 95.81725 | C168: 697.446 | D168: 11967.867 | E168: =D168+K168 -> 12588.162 | I168: 306.10322 | J168: 314.19185 | K168: =I168+J168 -> 620.29507 | M168: =SUM(K157:K168) -> 5524.6442 | N168: =D168*1000000 -> 1.1967867e+10
A169: 43466 | B169: 93.83012 | C169: 697.923 | D169: 12366.849 | E169: =D169+K169 -> 12945.886 | I169: 388.1709 | J169: 190.86656 | K169: =I169+J169 -> 579.03746 | N169: =D169*1000000 -> 1.2366849e+10
A170: 43497 | B170: 93.99516 | C170: 706.66 | D170: 11265.979 | E170: =D170+K170 -> 11596.345 | I170: 184.36927 | J170: 145.99639 | K170: =I170+J170 -> 330.36566 | N170: =D170*1000000 -> 1.1265979e+10
A171: 43525 | B171: 97.46835 | C171: 714.243 | D171: 11309.998 | E171: =D171+K171 -> 11686.183 | I171: 261.47114 | J171: 114.71336 | K171: =I171+J171 -> 376.1845 | N171: =D171*1000000 -> 1.1309998e+10
A172: 43556 | B172: 97.85911 | C172: 720.695 | D172: 12016.958 | E172: =D172+K172 -> 12498.897 | I172: 250.19996 | J172: 231.73887 | K172: =I172+J172 -> 481.93883 | N172: =D172*1000000 -> 1.2016958e+10
A173: 43586 | B173: 97.74813 | C173: 723.577 | D173: 11733.622 | E173: =D173+K173 -> 12063.732 | I173: 211.52017 | J173: 118.58988 | K173: =I173+J173 -> 330.11005 | N173: =D173*1000000 -> 1.1733622e+10
A174: 43617 | B174: 94.72392 | C174: 728.142 | D174: 11387.443 | E174: =D174+K174 -> 11731.14 | I174: 173.15827 | J174: 170.53881 | K174: =I174+J174 -> 343.69708 | N174: =D174*1000000 -> 1.1387443e+10
A175: 43647 | B175: 100.35459 | C175: 728.084 | D175: 11770.991 | E175: =D175+K175 -> 12128.222 | I175: 170.44266 | J175: 186.78809 | K175: =I175+J175 -> 357.23075 | N175: =D175*1000000 -> 1.1770991e+10
A176: 43678 | B176: 99.65265 | C176: 724.395 | D176: 11784.032 | E176: =D176+K176 -> 12213.872 | I176: 268.55221 | J176: 161.28849 | K176: =I176+J176 -> 429.8407 | N176: =D176*1000000 -> 1.1784032e+10
A177: 43709 | B177: 96.89753 | C177: 728.04 | D177: 12147.385 | E177: =D177+K177 -> 12419.142 | I177: 176.14925 | J177: 95.607381 | K177: =I177+J177 -> 271.75663 | N177: =D177*1000000 -> 1.2147385e+10
A178: 43739 | B178: 100.32094 | C178: 732.041 | D178: 12517.177 | E178: =D178+K178 -> 12935.143 | I178: 166.36942 | J178: 251.59728 | K178: =I178+J178 -> 417.9667 | N178: =D178*1000000 -> 1.2517177e+10
A179: 43770 | B179: 97.4951 | C179: 738.264 | D179: 12574.528 | E179: =D179+K179 -> 12950.857 | I179: 162.48519 | J179: 213.84354 | K179: =I179+J179 -> 376.32873 | N179: =D179*1000000 -> 1.2574528e+10
A180: 43800 | B180: 96.57002 | C180: 751.121 | D180: 13146.257 | E180: =D180+K180 -> 13738.252 | I180: 207.682 | J180: 384.31375 | K180: =I180+J180 -> 591.99575 | M180: =SUM(K169:K180) -> 4886.4528 | N180: =D180*1000000 -> 1.3146257e+10
A181: 43831 | B181: 94.02229 | C181: 751.82 | D181: 12929.806 | E181: =D181+K181 -> 13382.736 | I181: 205.33979 | J181: 247.59021 | K181: =I181+J181 -> 452.93 | N181: =D181*1000000 -> 1.2929806e+10
A182: 43862 | B182: 94.32496 | C182: 751.91 | D182: 11776.855 | E182: =D182+K182 -> 12215.327 | I182: 181.23804 | J182: 257.23315 | K182: =I182+J182 -> 438.47119 | N182: =D182*1000000 -> 1.1776855e+10
A183: 43891 | B183: 95.5975 | C183: 764.276 | D183: 12085.932 | E183: =D183+K183 -> 12359.885 | I183: 132.5651 | J183: 141.38798 | K183: =I183+J183 -> 273.95308 | N183: =D183*1000000 -> 1.2085932e+10
A184: 43922 | B184: 83.77999 | C184: 764.656 | D184: 10455.595 | E184: =D184+K184 -> 10757.087 | I184: 127.96554 | J184: 173.52681 | K184: =I184+J184 -> 301.49235 | N184: =D184*1000000 -> 1.0455595e+10
A185: 43952 | B185: 84.48458 | C185: 772.843 | D185: 9023.5288 | E185: =D185+K185 -> 9277.2183 | I185: 136.74332 | J185: 116.94616 | K185: =I185+J185 -> 253.68948 | N185: =D185*1000000 -> 9.0235288e+09
A186: 43983 | B186: 89.05611 | C186: 785.221 | D186: 9983.5437 | E186: =D186+K186 -> 10330.946 | I186: 196.97807 | J186: 150.42414 | K186: =I186+J186 -> 347.40221 | N186: =D186*1000000 -> 9.9835437e+09
A187: 44013 | B187: 95.69353 | C187: 803.584 | D187: 11348.727 | E187: =D187+K187 -> 11759.711 | I187: 237.3755 | J187: 173.60908 | K187: =I187+J187 -> 410.98458 | N187: =D187*1000000 -> 1.1348727e+10
A188: 44044 | B188: 95.2146 | C188: 834.713 | D188: 12277.308 | E188: =D188+K188 -> 12786.845 | I188: 321.85938 | J188: 187.6775 | K188: =I188+J188 -> 509.53688 | N188: =D188*1000000 -> 1.2277308e+10
A189: 44075 | B189: 96.06973 | C189: 862.259 | D189: 13098.35 | E189: =D189+K189 -> 13619.658 | I189: 388.79894 | J189: 132.5092 | K189: =I189+J189 -> 521.30814 | N189: =D189*1000000 -> 1.309835e+10
A190: 44105 | B190: 98.0114 | C190: 893.997 | D190: 13877.866 | E190: =D190+K190 -> 14299.665 | I190: 275.19156 | J190: 146.60786 | K190: =I190+J190 -> 421.79942 | N190: =D190*1000000 -> 1.3877866e+10
A191: 44136 | B191: 96.68445 | C191: 917.538 | D191: 14745.896 | E191: =D191+K191 -> 15159.975 | I191: 266.00397 | J191: 148.07447 | K191: =I191+J191 -> 414.07844 | N191: =D191*1000000 -> 1.4745896e+10
A192: 44166 | B192: 97.50686 | C192: 924.504 | D192: 14906.402 | E192: =D192+K192 -> 15439.836 | I192: 350.07302 | J192: 183.36121 | K192: =I192+J192 -> 533.43423 | M192: =SUM(K181:K192) -> 4879.08 | N192: =D192*1000000 -> 1.4906402e+10
A193: 44197 | B193: 92.10788 | C193: 951.395 | D193: 14133.474 | E193: =D193+K193 -> 14583.118 | I193: 295.59936 | J193: 154.04422 | K193: =I193+J193 -> 449.64358 | N193: =D193*1000000 -> 1.4133474e+10
...

Sheet PIB
B1: Data Focus | C1: 46024
V2: 151.36 | W2: 144.9 | X2: 145 | Y2: 144.28 | Z2: 144.15 | AA2: 140.89 | AB2: 145.14 | AC2: 155.83 | AD2: 155.2 | AE2: 148.86
C3: Jan | D3: Fev | E3: Mar | F3: Abr | G3: Mai | H3: Jun | I3: Jul | J3: Ago | K3: Set | L3: Out | M3: Nov | N3: Dez | O3: ANO
B4: 2023 - IBCBR | C4: 95.34045 | D4: 98.66432 | E4: 110.7489 | F4: 103.93825 | G4: 102.77755 | H4: 102.18912 | I4: 105.39607 | J4: 106.08707 | K4: 101.78181 | L4: 101.95461 | M4: 101.62017 | N4: 101.61385 | O4: =SUM(C4:N4) -> 1232.1122
B5: 2022 - ARIMA | C5: 132.27 | D5: 135.52 | E5: 147.06884 | F5: 141.48448 | G5: 137.17984 | H5: 138.27249 | I5: 147.50807 | J5: 140.48047 | K5: 139.51965 | L5: 140.86205 | M5: 147.01309 | N5: 147.04408 | O5: =SUM(C5:N5) -> 1694.2231
B6: 2022 - SEAS | C6: 132.27 | D6: 135.52 | E6: 147.06884 | F6: 141.48448 | G6: 137.07883 | H6: 138.45685 | I6: 148.87133 | J6: 141.83971 | K6: 144.82422 | L6: 143.0275 | M6: 147.2776 | N6: 148.99902 | O6: =SUM(C6:N6) -> 1706.7184
B8: Participação entre TRIs(ARIMA) | C8: =C5/SUM(C5:E5) -> 0.31883134 | D8: =D5/SUM(C5:E5) -> 0.32666533 | E8: =E5/SUM(C5:E5) -> 0.35450333 | F8: =F5/SUM(F5:H5) -> 0.33934274 | G8: =G5/SUM(F5:H5) -> 0.32901829 | H8: =H5/SUM(F5:H5) -> 0.33163897 | I8: =I5/SUM(I5:K5) -> 0.3450415 | J8: =J5/SUM(I5:K5) -> 0.32860299 | K8: =K5/SUM(I5:K5) -> 0.32635551 | L8: =L5/SUM(L5:N5) -> 0.32388095 | M8: =M5/SUM(L5:N5) -> 0.33802389 | N8: =N5/SUM(L5:N5) -> 0.33809516
B10: , | C10: =C4/SUM(C4:E4) -> 0.3128443 | D10: =D4/SUM(C4:E4) -> 0.32375105 | E10: =E4/SUM(C4:E4) -> 0.36340465 | F10: =F4/SUM(F4:H4) -> 0.33647327 | G10: =G4/SUM(F4:H4) -> 0.33271581 | H10: =H4/SUM(F4:H4) -> 0.33081092 | I10: =I4/SUM(I4:K4) -> 0.33644386 | J10: =J4/SUM(I4:K4) -> 0.33864966 | K10: =K4/SUM(I4:K4) -> 0.32490647 | L10: =L4/SUM($L$4:$N$4) -> 0.3340708 | M10: =M4/SUM($L$4:$N$4) -> 0.33297495 | N10: =N4/SUM($L$4:$N$4) -> 0.33295425
B11: Projeção PIB 2024
C13: 1º TRI | D13: 2º TRI | E13: 3º TRI | F13: 4º TRI | G13: ANO | H13: REF
B14: Variação Mesmo TRI 2023 | C14: =C15/SUM(C4:E4)-1 -> 0.0215076 | D14: =D15/SUM(F4:H4)-1 -> 0.035026862 | E14: =E15/SUM(I4:K4)-1 -> 0.049550867 | F14: =F15/SUM(L4:N4)-1 -> 0.04421649 | G14: 0.034944 | H14: 1278.5023
C15: =SUM(C19:E19) -> 311.30819 | D15: =SUM(F19:H19) -> 319.72489 | E15: =SUM(I19:K19) -> 328.7875 | F15: =SUM(L19:N19) -> 318.683 | G15: =SUM(C15:F15) -> 1278.5036
C18: Jan | D18: Fev | E18: Mar | F18: Abr | G18: Mai | H18: Jun | I18: Jul | J18: Ago | K18: Set | L18: Out | M18: Nov | N18: Dez | O18: ANO
B19: PIB 2024 Mensal | C19: 99.34698 | D19: 102.23245 | E19: 109.72876 | F19: 109.27855 | G19: 104.68456 | H19: 105.76178 | I19: 111.60656 | J19: 110.09329 | K19: 107.08765 | L19: 109.19097 | M19: 105.40349 | N19: 104.08854 | O19: =SUM(C19:N19) -> 1278.5036 | P19: =H14-O19 -> -0.00128
N20: =N19/SUM($N$19:$N$19) -> 1
B21: Previsão | C21: =C19 -> 99.34698 | D21: =D19 -> 102.23245 | E21: =E19 -> 109.72876 | F21: =F19 -> 109.27855 | G21: =G19 -> 104.68456 | H21: =H19 -> 105.76178 | I21: =I19 -> 111.60656 | J21: =J19 -> 110.09329 | ... M21: =M19 -> 105.40349 | N21: =N19+N20*$P$19 -> 104.08726 | O21: =SUM(C21:N21) -> 1278.5023
B26: Projeção PIB 2025
C28: 1º TRI | D28: 2º TRI | E28: 3º TRI | F28: 4º TRI | G28: ANO | H28: REF
B29: Variação Mesmo TRI 2024 | C29: =C30/SUM(C19:E19)-1 -> 0.040406293 | D29: =D30/SUM(F19:H19)-1 -> 0.026707273 | E29: =E30/SUM(I19:K19)-1 -> 0.012919469 | F29: =F30/SUM(L19:N19)-1 -> 0.011068435 | G29: 0.0226 | H29: =O21*(1+G29) -> 1307.3965
C30: =SUM(C33:E33) -> 323.887 | D30: =SUM(F33:H33) -> 328.26387 | E30: =SUM(I33:K33) -> 333.03526 | F30: =H29-SUM(C30:E30) -> 322.21032 | G30: =SUM(C30:F30) -> 1307.3965
C32: Jan | D32: Fev | E32: Mar | F32: Abr | G32: Mai | H32: Jun | I32: Jul | J32: Ago | K32: Set | L32: Out | M32: Nov | N32: Dez | O32: ANO
B33: PIB 2025 Mensal | C33: 102.8434 | D33: 106.89981 | E33: 114.14379 | F33: 112.54575 | G33: 108.51998 | H33: 107.19814 | I33: 113.16809 | J33: 110.42518 | K33: 109.44199 | L33: 109.61024 | M33: =$F$30*M8 -> 108.91479 | N33: =$F$30*N8 -> 108.93775 | O33: =SUM(C33:N33) -> 1312.6489 | P33: =H29-O33 -> -5.2524552
B35: Previsão | C35: =C33 -> 102.8434 | D35: =D33 -> 106.89981 | E35: =E33 -> 114.14379 | F35: =F33 -> 112.54575 | G35: =G33 -> 108.51998 | H35: =H33 -> 107.19814 | I35: =I33 -> 113.16809 | J35: =J33 -> 110.42518 | ... M35: =M33 -> 108.91479 | N35: =N33+N34*$P$33 -> 108.93775 | O35: =SUM(C35:N35) -> 1312.6489
B45: Projeção PIB 2026
C47: 1º TRI | D47: 2º TRI | E47: 3º TRI | F47: 4º TRI | G47: ANO | H47: REF
B48: Variação Mesmo TRI 2025 | C48: 0.0153 | D48: 0.0138 | E48: 0.018 | F48: =F49/SUM(L33:N33)-1 -> 0.024880792 | G48: 0.018 | H48: =O33*(1+G48) -> 1336.2766
C49: =C30*(1+C48) -> 328.84247 | D49: =D30*(1+D48) -> 332.79391 | E49: =E30*(1+E48) -> 339.02989 | F49: =H48-SUM(C49:E49) -> 335.61031 | G49: =SUM(C49:F49) -> 1336.2766
C51: Jan | D51: Fev | E51: Mar | F51: Abr | G51: Mai | H51: Jun | I51: Jul | J51: Ago | K51: Set | L51: Out | M51: Nov | N51: Dez | O51: ANO
B52: PIB 2025 Mensal | C52: =$C$49*C8 -> 104.84529 | D52: =$C$49*D8 -> 107.42143 | E52: =$C$49*E8 -> 116.57575 | F52: =$D$49*F8 -> 112.9312 | G52: =$D$49*G8 -> 109.49528 | H52: =$D$49*H8 -> 110.36743 | I52: =$E$49*I8 -> 116.97938 | J52: =$E$49*J8 -> 111.40624 | K52: =$E$49*K8 -> 110.64427 | L52: =$F$49*L8 -> 108.69779 | M52: =$F$49*M8 -> 113.4443 | N52: =$F$49*N8 -> 113.46822 | O52: =SUM(C52:N52) -> 1336.2766
B54: Previsão | C54: =C52 -> 104.84529 | D54: =D52 -> 107.42143 | E54: =E52 -> 116.57575 | F54: =F52 -> 112.9312 | G54: =G52 -> 109.49528 | H54: =H52 -> 110.36743 | I54: =I52 -> 116.97938 | J54: =J52 -> 111.40624 | ... M54: =M52 -> 113.4443 | N54: =N52+N53*$P$33 -> 113.46822 | O54: =SUM(C54:N54) -> 1336.2766

Sheet IGP-DI
A1: Data
A2: 44531 | B2: 1088.489 | E2: =B2 -> 1088.489
A3: 44562 | B3: 1110.398 | E3: =B3 -> 1110.398
A4: 44593 | B4: 1127.077 | E4: =B4 -> 1127.077
A5: 44621 | B5: 1153.777 | E5: =B5 -> 1153.777
A6: 44652 | B6: 1158.546 | E6: =B6 -> 1158.546
A7: 44682 | B7: 1166.542 | E7: =B7 -> 1166.542
A8: 44713 | B8: 1173.831 | E8: =B8 -> 1173.831
A9: 44743 | B9: 1169.426 | E9: =B9 -> 1169.426
A10: 44774 | B10: 1162.956 | E10: =B10 -> 1162.956
A11: 44805 | B11: 1148.811 | E11: =B11 -> 1148.811
A12: 44835 | B12: 1141.733 | E12: =B12 -> 1141.733
A13: 44866 | B13: 1139.734 | E13: =B13 -> 1139.734
... A25: 45231 | B25: 1098.48 | E25: =B25 -> 1098.48
A26: 45261 | B26: 1105.541 | D26: =B26/B14-1 -> -0.03296289 | E26: =B26 -> 1105.541
A27: 45292 | B27: 1102.571 | E27: =B27 -> 1102.571
A28: 45323 | B28: 1098.095 | E28: =B28 -> 1098.095
A29: 45352 | B29: 1094.763 | E29: =B29 -> 1094.763
A30: 45383 | B30: 1102.66 | E30: =B30 -> 1102.66
A31: 45413 | B31: 1112.26 | E31: =B31 -> 1112.26
A32: 45444 | B32: 1117.787 | E32: =B32 -> 1117.787
A33: 45474 | B33: 1127.101 | E33: =B33 -> 1127.101
A34: 45505 | B34: 1128.408 | E34: =B34 -> 1128.408
A35: 45536 | B35: 1139.981 | E35: =B35 -> 1139.981
A36: 45566 | B36: 1157.516 | E36: 1157.516 | J36: 2024 | K36: 2025 | L36: 2026
A37: 45597 | B37: 1171.21 | E37: 1171.21 | J37: 6.6059 | K37: -0.79 | L37: 3.94
A38: 45627 | B38: 1181.407 | D38: =B38/B26-1 -> 0.068623416 | E38: 1181.407 | L38: Tabela de | M38: ajuste | O38: 1182.693
A39: 45658 | B39: 1182.693 | C39: 0.4285 | E39: =E38*(1+F39%) -> 1180.9562 | F39: =((((C39/100)+1)*$H$51)-1)*100 -> -0.038159266 | L39: 1181.407 | O39: 1194.518
A40: 45689 | B40: 1194.518 | C40: 0.5 | E40: =E39*(1+F40%) -> 1181.346 | F40: =((((C40/100)+1)*$H$51)-1)*100 -> 0.033008496 | L40: =L39*(1+M40%) -> 1186.4693 | M40: =C39 -> 0.4285 | O40: 1188.55
A41: 45717 | B41: 1188.55 | C41: 0.4923 | E41: =E40*(1+F41%) -> 1181.6454 | F41: =((((C41/100)+1)*$H$51)-1)*100 -> 0.025344275 | L41: =L40*(1+M41%) -> 1192.4017 | M41: =C40 -> 0.5 | O41: 1192.079
A42: 45748 | B42: 1192.079 | C42: 0.39 | E42: =E41*(1+F42%) -> 1180.7417 | F42: =((((C42/100)+1)*$H$51)-1)*100 -> -0.076480369 | L42: =L41*(1+M42%) -> 1198.2719 | M42: =C41 -> 0.4923 | O42: 1181.945
A43: 45778 | B43: 1181.945 | C43: 0.31 | E43: =E42*(1+F43%) -> 1178.8984 | F43: =((((C43/100)+1)*$H$51)-1)*100 -> -0.15610863 | L43: =L42*(1+M43%) -> 1202.9451 | M43: =C42 -> 0.39 | O43: 1160.613
A44: 45809 | B44: 1160.613 | C44: 0.33 | E44: =E43*(1+F44%) -> 1177.2928 | F44: =((((C44/100)+1)*$H$51)-1)*100 -> -0.13620157 | L44: =L43*(1+M44%) -> 1206.6743 | M44: =C43 -> 0.31 | O44: 1159.851
A45: 45839 | B45: 1159.851 | C45: 0.27 | E45: =E44*(1+F45%) -> 1174.9862 | F45: =((((C45/100)+1)*$H$51)-1)*100 -> -0.19592277 | L45: =L44*(1+M45%) -> 1210.6563 | M45: =C44 -> 0.33 | O45: 1162.219
A46: 45870 | B46: 1162.219 | C46: 0.31 | E46: =E45*(1+F46%) -> 1173.1519 | F46: =((((C46/100)+1)*$H$51)-1)*100 -> -0.15610863 | L46: =L45*(1+M46%) -> 1213.9251 | M46: =C45 -> 0.27 | O46: 1166.349
A47: 45901 | B47: 1166.349 | C47: 0.425 | E47: =E46*(1+F47%) -> 1172.6634 | F47: =((((C47/100)+1)*$H$51)-1)*100 -> -0.041643003 | L47: =L46*(1+M47%) -> 1217.6882 | M47: =C46 -> 0.31 | O47: 1165.98
A48: 45931 | B48: 1165.98 | C48: 0.46 | E48: =E47*(1+F48%) -> 1172.5836 | F48: =((((C48/100)+1)*$H$51)-1)*100 -> -0.0068056369 | L48: =L47*(1+M48%) -> 1222.8634 | M48: =C47 -> 0.425 | O48: 1165.072 | P48: =O48/E37-1 -> -0.0052407339
A49: 45962 | B49: 1165.072 | C49: 0.45 | E49: =E48*(1+F49%) -> 1172.3871 | F49: =((((C49/100)+1)*$H$51)-1)*100 -> -0.01675917 | L49: =L48*(1+M49%) -> 1228.4886 | M49: =C48 -> 0.46
A50: 45992 | B50: =G50 -> 1172.0739 | C50: 0.44 | D50: =B50/B38-1 -> -0.0079 | E50: =E49*(1+F50%) -> 1172.0739 | F50: =((((C50/100)+1)*$H$51)-1)*100 -> -0.026712703 | G50: =E38*(1+K37%) -> 1172.0739 | H50: =G50/L51 -> 0.94564303 | L50: =L49*(1+M50%) -> 1234.0168 | M50: =C49 -> 0.45
A51: 46023 | B51: =B50*(1+($G$62/$B$50)^(1/12)-1) -> 1175.8544 | H51: =H50^(1/12) -> 0.99535332 | L51: =L50*(1+M51%) -> 1239.4464 | M51: =C50 -> 0.44
...

Sheet Procedimentos
A1: Distribuição Mensal
B3: Calcular a participação de cada mês no seu respectivo trimestre (Previsão ARIMA ou baseado nos anos anteriores)
A5: Projeção PIB
B7: Obter variações trimestrais no Sistema de expectativas do Bacen
B8: Obter variação anual no SE-BCB
B9: Aplicar para o 1º, 2º e 3º trimestre o percentual obtido no SE
B10: Estabelecer o 4º Tri para que a variação seja igual à expectativa anual do SE
B11: Distribuir os valores trimestrais nos meses de acordo com os percentuais da primeira etapa.
A13: Projeção IGP-DI
B15: Obter variações mensais no Sistema de expectativas do Bacen
B16: Obter variação anual no SE-BCB
B17: Ajustar para o valor final coincidir com a projeção anual
